Workbook
Name AnnualSalary: humanresource!$J$2:$J$804
Name CitizenDesc: humanresource!$P$2:$P$804
Name DateofHire: humanresource!$R$2:$R$804
Name DateofTermination: humanresource!$S$2:$S$804
Name Department: humanresource!$F$2:$F$804
Name DOB: humanresource!$K$2:$K$804
Name EmpID: humanresource!$A$2:$A$804
Name EmployeeName: humanresource!$B$2:$B$804
Name EmployeSatisfaction: humanresource!$AC$2:$AC$804
Name EmploymentStatus: humanresource!$W$2:$W$804
Name EmpStatusID: humanresource!$V$2:$V$804
Name EngagementSurvey: humanresource!$AB$2:$AB$804
Name FromDiversityJobFairID: humanresource!$X$2:$X$804
Name GenderID: humanresource!$E$2:$E$804
Name HispanicLatino: humanresource!$O$2:$O$804
Name HR_DATA: humanresource[#All]
Name LastPerformanceReview: humanresource!$AE$2:$AE$804
Name LateDaysLast30: humanresource!$AF$2:$AF$804
Name Leaves: humanresource!$AG$2:$AG$804
Name ManagerName: humanresource!$H$2:$H$804
Name MaritialStatus: humanresource!$D$2:$D$804
Name MarriedID: humanresource!$C$2:$C$804
Name NativeTimeline_DateofHire: #N/A
Name PerformanceScore: humanresource!$AA$2:$AA$804
Name PerfScoreID: humanresource!$Z$2:$Z$804
Name Position: humanresource!$G$2:$G$804
Name RaceDescription: humanresource!$Q$2:$Q$804
Name RecruitmentSource: humanresource!$Y$2:$Y$804
Name Salary: humanresource!$I$2:$I$804
Name Sex: humanresource!$L$2:$L$804
Name Slicer_Department: #N/A
Name Slicer_GenderID: #N/A
Name Slicer_ManagerName: #N/A
Name Slicer_Position: #N/A
Name Slicer_Sex: #N/A
Name Slicer_State: #N/A
Name SpecialProjects: humanresource!$AD$2:$AD$804
Name State: humanresource!$M$2:$M$804
Name Termd: humanresource!$T$2:$T$804
Name TermReason: humanresource!#REF!
Name Zip: humanresource!$N$2:$N$804

Sheet PivotField
A2: Employee Count By Department
A3: Row Labels | B3: Count of EmpID
A4: Admin Offices | B4: 9
A5: Executive Office | B5: 1
A6: Finance | B6: 69
A7: HR | B7: 90
A8: IT | B8: 90
A9: IT/IS | B9: 50
A10: Production | B10: 80
A11: Production | B11: 201
A12: R&D | B12: 89
A13: Sales | B13: 113
A14: Software Engineering | B14: 11
A15: Grand Total | B15: 803
A17: Average Salary Per Department
A18: Row Labels | B18: Average of Salary
A19: Admin Offices | B19: 71791.889
A20: Executive Office | B20: 250000
A21: Finance | B21: 74777.188
A22: HR | B22: 74270.444
A23: IT | B23: 76122.078
A24: IT/IS | B24: 97064.64
A25: Production | B25: 75146
A26: Production | B26: 60002.139
A27: R&D | B27: 73267.607
A28: Sales | B28: 72090.664
A29: Software Engineering | B29: 94989.455
A30: Grand Total | B30: 72513.534
A32: Manager count | J32: Employee Count Based On HaspanicLatino Status | S32: Employee Count Based On Hire Year
A33: Row Labels | B33: Count of ManagerName | J33: Row Labels | K33: Count of EmpID | S33: Row Labels | T33: Count of EmpID
A34: Admin Offices | B34: 9 | J34: No | K34: 520 | S34: 2006 | T34: 1
A35: Executive Office | B35: 1 | J35: Yes | K35: 283 | S35: 2007 | T35: 2
A36: Finance | B36: 69 | J36: Grand Total | K36: 803 | S36: 2008 | T36: 3
A37: HR | B37: 90 | S37: 2009 | T37: 7
A38: IT | B38: 90 | S38: 2010 | T38: 9
A39: IT/IS | B39: 50 | S39: 2011 | T39: 82
A40: Production | B40: 80 | S40: 2012 | T40: 45
A41: Production | B41: 201 | S41: 2013 | T41: 41
A42: R&D | B42: 89 | S42: 2014 | T42: 58
A43: Sales | B43: 113 | J43: Terminated Employees | S43: 2015 | T43: 43
...

Sheet humanresource
A1: EmpID | B1: EmployeeName | C1: MarriedID | D1: MaritialStatus | E1: GenderID | F1: Department | G1: Position | H1: ManagerName | I1: Salary | J1: AnnualSalary | K1: DOB | L1: Sex | M1: State | N1: Zip | O1: HispanicLatino | P1: CitizenDesc | Q1: RaceDescription | R1: DateofHire | S1: DateofTermination | T1: Termd | U1: TerminationReason | V1: EmpStatusID | W1: EmploymentStatus | X1: FromDiversityJobFairID | Y1: RecruitmentSource | Z1: PerfScoreID | AA1: PerformanceScore | AB1: EngagementSurvey | AC1: EmployeSatisfaction | AD1: SpecialProjects | AE1: LastPerformanceReview | AF1: LateDaysLast30 | AG1: Leaves
A2: 10001 | B2: Calvin Candie | C2: Single | D2: Single | E2: Male | F2: Production | G2: Production Manager | H2: Janet King | I2: 72640 | J2: 871680 | K2: 30537 | L2: M | M2: MA | N2: 2169 | O2: No | P2: US Citizen | Q2: White | R2: 42397 | S2: Not Terminated | T2: 0 | U2: Active | V2: 1 | W2: Active | X2: 0 | Y2: Indeed | Z2: 4 | AA2: Exceeds | AB2: 5 | AC2: Neutral | AD2: 0 | AE2: 43518 | AF2: 0 | AG2: 14
A3: 10002 | B3: Linda Anderson | C3: Single | D3: Single | E3: Female | F3: Production | G3: Production Technician I | H3: Amy Dunn | I3: 57568 | J3: 690816 | K3: 28267 | L3: F | M3: MA | N3: 1844 | O3: No | P3: US Citizen | Q3: White | R3: 40917 | S3: Not Terminated | T3: 0 | U3: Active | V3: 1 | W3: Active | X3: 0 | Y3: LinkedIn | Z3: 4 | AA3: Exceeds | AB3: 5 | AC3: Very Satisfied | AD3: 0 | AE3: 43472 | AF3: 0 | AG3: 15
A4: 10003 | B4: Helen Billis | C4: Married | D4: Married | E4: Female | F4: Production | G4: Production Technician I | H4: Brannon Miller | I4: 62910 | J4: 754920 | K4: 32752 | L4: F | M4: MA | N4: 2031 | O4: No | P4: US Citizen | Q4: White | R4: 41827 | S4: Not Terminated | T4: 0 | U4: Active | V4: 1 | W4: Active | X4: 0 | Y4: Indeed | Z4: 4 | AA4: Exceeds | AB4: 5 | AC4: Neutral | AD4: 0 | AE4: 43523 | AF4: 0 | AG4: 19
A5: 10004 | B5: Lindsay Lynch | C5: Single | D5: Single | E5: Female | F5: Production | G5: Production Technician I | H5: Webster Butler | I5: 47434 | J5: 569208 | K5: 26709 | L5: F | M5: MA | N5: 1844 | O5: Yes | P5: US Citizen | Q5: Black or African American | R5: 40854 | S5: 2015-11-14 | T5: 1 | U5: Another Position | V5: 5 | W5: Voluntarily Terminated | X5: 1 | Y5: Diversity Job Fair | Z5: 4 | AA5: Exceeds | AB5: 5 | AC5: Satisfied | AD5: 0 | AE5: 42037 | AF5: 0 | AG5: 17
A6: 10004 | B6: Juan Gregory | C6: Single | D6: Single | E6: Male | F6: R&D | G6: Manager | H6: Amy Christian | I6: 57460 | J6: 689520 | K6: 24041 | L6: F | M6: CA | N6: 99044 | O6: No | P6: Non-Citizen | Q6: White | R6: 44149 | S6: Not Terminated | T6: 0 | U6: Active | V6: 1 | W6: Terminated for Cause | X6: 1 | Y6: Referral | Z6: 4 | AA6: Fully Meets | AB6: 3.7 | AC6: Dissatisfied | AD6: 1 | AE6: 45769 | AF6: 4 | AG6: 9
A7: 10005 | B7: Lucas Patronick | C7: Single | D7: Single | E7: Male | F7: Software Engineering | G7: Software Engineer | H7: Alex Sweetwater | I7: 108987 | J7: 1307844 | K7: 28906 | L7: M | M7: MA | N7: 1844 | O7: No | P7: US Citizen | Q7: Black or African American | R7: 40854 | S7: 2015-09-07 | T7: 1 | U7: Another Position | V7: 5 | W7: Voluntarily Terminated | X7: 1 | Y7: Diversity Job Fair | Z7: 4 | AA7: Exceeds | AB7: 5 | AC7: Very Satisfied | AD7: 3 | AE7: 42232 | AF7: 0 | AG7: 13
A8: 10005 | B8: James Gordon | C8: Married | D8: Married | E8: Male | F8: HR | G8: Sales Executive | H8: Virginia Hanson | I8: 70586 | J8: 847032 | K8: 37085 | L8: F | M8: NY | N8: 72697 | O8: No | P8: Non-Citizen | Q8: Hispanic | R8: 43563 | S8: 2024-11-28 | T8: 0 | U8: Active | V8: 2 | W8: Voluntarily Terminated | X8: 1 | Y8: Indeed | Z8: 1 | AA8: Fully Meets | AB8: 3.7 | AC8: Very Dissatisfied | AD8: 5 | AE8: 45752 | AF8: 5 | AG8: 0
A9: 10006 | B9: Elle Driver | C9: Single | D9: Single | E9: Female | F9: Sales | G9: Area Sales Manager | H9: Lynn Daneault | I9: 74241 | J9: 890892 | K9: 32455 | L9: F | M9: CA | N9: 90007 | O9: No | P9: US Citizen | Q9: White | R9: 40553 | S9: Not Terminated | T9: 0 | U9: Active | V9: 1 | W9: Active | X9: 0 | Y9: Indeed | Z9: 4 | AA9: Exceeds | AB9: 4.77 | AC9: Very Satisfied | AD9: 0 | AE9: 43492 | AF9: 0 | AG9: 14
A10: 10006 | B10: Brian Browning | C10: Married | D10: Divorced | E10: Female | F10: Finance | G10: Production Technician I | H10: Mr. Jason Roth | I10: 65545 | J10: 786540 | K10: 28803 | L10: M | M10: FL | N10: 3644 | O10: No | P10: US Citizen | Q10: White | R10: 45944 | S10: Not Terminated | T10: 1 | U10: Terminated | V10: 2 | W10: Voluntarily Terminated | X10: 0 | Y10: LinkedIn | Z10: 1 | AA10: PIP | AB10: 3.2 | AC10: Dissatisfied | AD10: 5 | AE10: 45765 | AF10: 1 | AG10: 5
A11: 10007 | B11: Kara Harrison | C11: Married | D11: Married | E11: Female | F11: Production | G11: Production Technician I | H11: Amy Dunn | I11: 62065 | J11: 744780 | K11: 27151 | L11: F | M11: MA | N11: 1886 | O11: No | P11: US Citizen | Q11: White | R11: 41771 | S11: Not Terminated | T11: 0 | U11: Active | V11: 1 | W11: Active | X11: 0 | Y11: CareerBuilder | Z11: 4 | AA11: Exceeds | AB11: 4.76 | AC11: Satisfied | AD11: 0 | AE11: 43511 | AF11: 0 | AG11: 5
A12: 10007 | B12: Sarah Kim | C12: Married | D12: Single | E12: Male | F12: Sales | G12: Production Technician I | H12: Rachel Davis | I12: 99873 | J12: 1198476 | K12: 27330 | L12: F | M12: FL | N12: 18402 | O12: No | P12: US Citizen | Q12: Other | R12: 43036 | S12: Not Terminated | T12: 1 | U12: Terminated | V12: 2 | W12: Active | X12: 0 | Y12: Referral | Z12: 4 | AA12: Fully Meets | AB12: 4.7 | AC12: Neutral | AD12: 3 | AE12: 45909 | AF12: 2 | AG12: 4
A13: 10008 | B13: Leonara Lindsay | C13: Single | D13: Single | E13: Female | F13: IT/IS | G13: IT Support | H13: Eric Dougall | I13: 51777 | J13: 621324 | K13: 32421 | L13: F | M13: CT | N13: 6070 | O13: Yes | P13: US Citizen | Q13: Black or African American | R13: 40564 | S13: Not Terminated | T13: 0 | U13: Active | V13: 1 | W13: Active | X13: 1 | Y13: Diversity Job Fair | Z13: 4 | AA13: Exceeds | AB13: 4.64 | AC13: Satisfied | AD13: 5 | AE13: 43490 | AF13: 0 | AG13: 14
... A804: 11004 | B804: Amy Flores | C804: Married | D804: Married | E804: Female | F804: HR | G804: Production Technician I | H804: Heather Sanchez | I804: 105863 | J804: 1270356 | K804: 34106 | L804: F | M804: NY | N804: 97645 | O804: Yes | P804: Non-Citizen | Q804: Black | R804: 44306 | S804: Not Terminated | T804: 0 | U804: Active | V804: 3 | W804: Voluntarily Terminated | X804: 1 | Y804: Indeed | Z804: 1 | AA804: Exceeds Expectations | AB804: 3.3 | AC804: Very Dissatisfied | AD804: 1 | AE804: 45998 | AF804: 0 | AG804: 5

Sheet Dashboard

Sheet KPI's
C2: KPI's | G2: Employee Data | H2: GenderID
C3: Total Employee Count | D3: =COUNTIF(Termd,0) -> 463 | G3: 10026 | H3: =INDEX(humanresource[#All],MATCH(G3,humanresource[[#All],[EmpID]],0),MATCH(H2,humanresource[#Headers],0)) -> Male
C5: Employees Left | D5: =COUNTIF(Termd,1) -> 340
C6: Attrition Rate Percentage | D6: =COUNTIF(Termd,1)/COUNTA(EmpID) -> 0.4234122 | G6: EmpID | H6: EmployeeName | I6: MarriedID | J6: MaritialStatus | K6: GenderID | L6: Department | M6: Position | N6: ManagerName | O6: Salary | P6: AnnualSalary | Q6: DOB | R6: Sex | S6: State | T6: Zip | U6: HispanicLatino | V6: CitizenDesc | W6: RaceDescription | X6: DateofHire | Y6: DateofTermination | Z6: Termd | AA6: TerminationReason | AB6: EmpStatusID | AC6: EmploymentStatus | AD6: FromDiversityJobFairID | AE6: RecruitmentSource | AF6: PerfScoreID | AG6: PerformanceScore | AH6: EngagementSurvey | AI6: EmployeSatisfaction | AJ6: SpecialProjects | AK6: LastPerformanceReview | AL6: LateDaysLast30 | AM6: Leaves
G7: 10114 | H7: =VLOOKUP($G$7,humanresource[#All],MATCH('KPI''s'!H6,humanresource[#Headers],0),FALSE) -> Linda Bachiochi | I7: =VLOOKUP($G$7,humanresource[#All],MATCH('KPI''s'!I6,humanresource[#Headers],0),FALSE) -> Single | J7: =VLOOKUP($G$7,humanresource[#All],MATCH('KPI''s'!J6,humanresource[#Headers],0),FALSE) -> Single | K7: =VLOOKUP($G$7,humanresource[#All],MATCH('KPI''s'!K6,humanresource[#Headers],0),FALSE) -> Female | L7: =VLOOKUP($G$7,humanresource[#All],MATCH('KPI''s'!L6,humanresource[#Headers],0),FALSE) -> Production | M7: =VLOOKUP($G$7,humanresource[#All],MATCH('KPI''s'!M6,humanresource[#Headers],0),FALSE) -> Production Technician I | N7: =VLOOKUP($G$7,humanresource[#All],MATCH('KPI''s'!N6,humanresource[#Headers],0),FALSE) -> Brannon Miller | O7: =VLOOKUP($G$7,humanresource[#All],MATCH('KPI''s'!O6,humanresource[#Headers],0),FALSE) -> 47837 | ... AM7: =VLOOKUP($G$7,humanresource[#All],MATCH('KPI''s'!AM6,humanresource[#Headers],0),FALSE) -> 4
C8: Average Performance Score | D8: =AVERAGE(PerfScoreID) -> 2.6787049
H9: =MATCH(H6,humanresource[#Headers],0) -> 2 | I9: =MATCH(I6,humanresource[#Headers],0) -> 3 | J9: =MATCH(J6,humanresource[#Headers],0) -> 4 | K9: =MATCH(K6,humanresource[#Headers],0) -> 5 | L9: =MATCH(L6,humanresource[#Headers],0) -> 6 | M9: =MATCH(M6,humanresource[#Headers],0) -> 7 | N9: =MATCH(N6,humanresource[#Headers],0) -> 8 | O9: =MATCH(O6,humanresource[#Headers],0) -> 9 | P9: =MATCH(P6,humanresource[#Headers],0) -> 10
C10: Avg. Engagement Survey | D10: =AVERAGE(EngagementSurvey) -> 3.8828892
G11: EmpID | H11: EmployeeName | I11: GenderID | J11: Department | K11: Position | L11: ManagerName | M11: Salary | N11: AnnualSalary | O11: TerminationReason | P11: PerfScoreID | Q11: EngagementSurvey | R11: SpecialProjects | S11: Leaves
C12: Average Leaves | D12: =AVERAGE(Leaves) -> 7.0635118 | G12: 10499 | H12: =VLOOKUP($G$12,humanresource[#All],MATCH(H11,humanresource[#Headers],0),FALSE) -> Jennifer Black | I12: =VLOOKUP($G$12,humanresource[#All],MATCH(I11,humanresource[#Headers],0),FALSE) -> Male | J12: =VLOOKUP($G$12,humanresource[#All],MATCH(J11,humanresource[#Headers],0),FALSE) -> HR | K12: =VLOOKUP($G$12,humanresource[#All],MATCH(K11,humanresource[#Headers],0),FALSE) -> Production Technician I | L12: =VLOOKUP($G$12,humanresource[#All],MATCH(L11,humanresource[#Headers],0),FALSE) -> Jessica Burton | M12: =VLOOKUP($G$12,humanresource[#All],MATCH(M11,humanresource[#Headers],0),FALSE) -> 88538 | N12: =VLOOKUP($G$12,humanresource[#All],MATCH(N11,humanresource[#Headers],0),FALSE) -> 1062456 | O12: =VLOOKUP($G$12,humanresource[#All],MATCH(O11,humanresource[#Headers],0),FALSE) -> Active | ... S12: =VLOOKUP($G$12,humanresource[#All],MATCH(S11,humanresource[#Headers],0),FALSE) -> 4
C14: Average Salary | D14: =AVERAGE(Salary) -> 72513.534
C16: Employees hired in 2025 | D16: =COUNTIFS(humanresource[DateofHire],">=01-01-2025",humanresource[DateofHire],"<=31-12-2025") -> 42
